<mujoco>
    <body name="robot0:base_link" pos="0 0 0.0" >
        <!-- husky_ptu_tilt for camera -->
        <body name="husky_ptu_tilt_link" pos="0.345 -0.000586 0.51176" quat="0.707105 -0.707108 0 0">
            <inertial pos="0 0 0" mass="0.65" diaginertia="0.0001 0.0001 0.0001" />
            <joint name="husky_ptu_pan" pos="0 0 0" axis="0 -1 0" limited="true" range="-2.775 2.775" />
            <geom pos="-0.0295 0.011 0" quat="0.000796327 1 0 0" type="mesh" contype="0" conaffinity="0" group="1" rgba="0.3 0.3 0.3 1" mesh="flir-ptu-simple" />
            <geom size="0.0225 0.0325 0.022" pos="0 0.011 0" type="box" rgba="0.3 0.3 0.3 1" />
            <geom size="0.023 0.022 0.022" pos="-0.045 0.0215 0" type="box" rgba="0.3 0.3 0.3 1" />
            <geom size="0.005 0.0075" pos="-0.074 0.021 0" quat="0.707388 0 0.706825 0" type="cylinder" rgba="0.3 0.3 0.3 1" />
            <body name="husky_ptu_tilted_link" pos="0 0 0" quat="0.707105 -0.707108 0 0">
                <inertial pos="0 1.63383e-07 -0.0613599" quat="0.499998 0.500002 0.499998 0.500002" mass="0.342012" diaginertia="0.000766531 0.000739434 0.000100971" />
                <joint name="husky_ptu_tilt" pos="0 0 0" axis="0 1 0" limited="true" range="-0.82 0.52" />
                <geom pos="0 1.63384e-07 -0.06136" quat="0.499998 0.50005 0.499998 0.499954" type="mesh" contype="0" conaffinity="0" group="1" mesh="pointgrey_bumblebee2" class="bb2_camera" />
                <geom size="0.0237 0.0785 0.018" pos="0 1.63384e-07 -0.06136" quat="-3.67321e-06 1 0 0" type="box" />
            </body>
        </body>

        <include file="dual_arm/robot_ur5_l.xml"></include>
        <include file="dual_arm/robot_ur5_r.xml"></include>
    </body>
</mujoco>
