<mujoco>
    <body name="robot" pos="0 0 -0.14" quat="1 0 0 0.707">
        <!-- site for root imu sensor -->
        <site name="imu" size="0.01" pos="0 0 0" />

        <geom size="0.28 0.165" pos="0 0 0.2" type="cylinder" rgba="0.356 0.361 0.376 1"/>
        <geom pos="-0.12465 0.23892 0.31127" quat="0.707105 0.707108 0 0" type="mesh" rgba="0.8 0 0 1" mesh="estop_link"/>
        <geom pos="0.235 0 0.2878" quat="0 1 0 0" type="mesh" rgba="0.792157 0.819608 0.933333 1" mesh="laser_link"/>
        <geom pos="-0.086875 0 0.377425" type="mesh" rgba="0.086 0.506 0.767 1" mesh="torso_fixed_link"/>

        <body name="torso_lift_link" pos="-0.086875 0 0.37">
            <inertial pos="-0.000983929 -0.000886078 0.286874" quat="0.99962 -0.000833361 0.0269789 0.00565622" mass="10.949" diaginertia="0.370106 0.367813 0.0963668"/>
            <joint name="torso_lift_joint" pos="0 0 0" axis="0 0 1" type="slide" range="0.37 0.4" damping="100"/>
            <geom type="mesh" rgba="1 1 1 1" mesh="torso_lift_link_collision"/>
            <!--
            <body name="l_hand" pos="-0.07 0.11 0.08">
                <geom type="mesh" rgba="1 1 1 1" mesh="thing" pos="0.0 0.0 0.0" quat="1 0 0 1"/>
                <include file="robots/fetch_dual/l_shoulder.xml"></include>
            </body>
            -->
            <body name="r_hand" pos="-0.07 -0.11 0.08">
                <geom type="mesh" rgba="1 1 1 1" mesh="thing" pos="0.0 0.0 0.0" quat="-1 0 0 1"/>
                <include file="robots/fetch_dual/r_shoulder.xml"></include>
            </body>

            <geom type="mesh" rgba="0 0 0 1" mesh="bellows_link_collision"/>
            <body name="head_pan_link" pos="0.053125 0 0.603001">
                <camera name="egocentric_camera" pos="0 0 .0" xyaxes="0 -1 0 1 0 2" fovy="100" mode="targetbody"/>
                <inertial pos="0.0321 0.0161 0.039" quat="0.514814 0.545129 -0.452957 0.482318" mass="2.2556" diaginertia="0.0184878 0.0128242 0.00948808"/>
                <!-- <joint name="head_pan_joint" pos="0 0 0" axis="0 0 1" range="-1.57 1.57"/> -->
                <geom type="mesh" rgba="0.356 0.361 0.376 1" mesh="head_pan_link_collision"/>
                <body name="head_tilt_link" pos="0.14253 0 0.057999">
                    <inertial pos="0.0081 0.0025 0.0113" quat="0.645806 0.659961 -0.274048 0.268857" mass="0.9087" diaginertia="0.00630102 0.00590111 0.00139787"/>
                    <!-- <joint name="head_tilt_joint" pos="0 0 0" axis="0 1 0" range="-0.76 1.45"/> -->
                    <geom type="mesh" rgba="0.086 0.506 0.767 1" mesh="head_tilt_link_collision"/>
                </body>
            </body>
        </body>
    </body>
</mujoco>
